<?xml version="1.0"?>
<robot name="robotiq_85_gripper" xmlns:xacro="http://ros.org/wiki/xacro">

  <xacro:include filename="$(find robotiq_85_description)/urdf/robotiq_85_gripper.transmission.xacro" />

  <xacro:macro name="robotiq_85_gripper" params="
    name
    prefix
    parent
    *origin
    use_fake_hardware:=false
    fake_sensor_commands:=false
    gazebo_sim:=false
    ignition_sim:=false
    use_ros2_control:=false">

    <!-- The current hardware driver does not depend on ros2_control but we do utilize
    it for simulating the gripper in Gazebo. Enabling this on hardware causes the
    JointStateBroadcaster to publish values for all joints including ones that are
    mimic'd which is causing issues on systems consuming the joint_state data. -->
    <xacro:if value="${use_ros2_control}">
      <!-- ros2 control include -->
      <xacro:include filename="$(find robotiq_85_description)/urdf/robotiq_85_gripper.ros2_control.xacro"/>
      <!-- ros2 control instance -->
      <xacro:robotiq_85_gripper_ros2_control name="RobotiqGripperSystem"/>
    </xacro:if>

    <joint name="${prefix}robotiq_85_base_joint" type="fixed">
      <parent link="${parent}"/>
      <child link="${prefix}robotiq_85_base_link"/>
      <xacro:insert_block name="origin"/>
    </joint>

    <link name="${prefix}robotiq_85_base_link">
      <!-- Visual aid for grasping -->
      <visual>
        <origin xyz="0.16 0 0" rpy="0 0 0" />
        <geometry>
          <sphere radius="0.007"/>
        </geometry>
        <material name="">
          <color rgba="0 1.0 0 1.0"/>
        </material>
      </visual>
      <!-- Gripper body -->
      <visual>
        <geometry>
          <mesh filename="file://$(find robotiq_85_description)/meshes/visual/robotiq_85_base_link.dae"/>
        </geometry>
      </visual>
      <collision>
        <geometry>
          <mesh filename="file://$(find robotiq_85_description)/meshes/collision/robotiq_85_base_link.stl"/>
        </geometry>
      </collision>
      <inertial>
        <mass value="0.636951" />
        <origin xyz="0.0 0.0 0.0" />
        <inertia ixx = "0.000380" ixy = "0.000000" ixz = "0.000000"
          iyx = "0.000000" iyy = "0.001110" iyz = "0.000000"
          izx = "0.000000" izy = "0.000000" izz = "0.001171" />
      </inertial>
    </link>

    <joint name="${prefix}robotiq_85_left_knuckle_joint" type="revolute">
      <parent link="${prefix}robotiq_85_base_link"/>
      <child link="${prefix}robotiq_85_left_knuckle_link"/>
      <axis xyz="0 0 1"/>
      <origin rpy="${pi} 0.0 0.0" xyz="0.05490451627 0.03060114443 0.0"/>
      <limit lower="0.0" upper="0.804" velocity="0.5" effort="50"/>
      <dynamics damping="100.0" />
    </joint>
    <gazebo reference="${prefix}robotiq_85_left_knuckle_link">
      <kp>1000000.0</kp>
      <kd>100.0</kd>
      <mu1>30.0</mu1>
      <mu2>30.0</mu2>
      <maxVel>1.0</maxVel>
      <minDepth>0.001</minDepth>
      <material>Gazebo/Grey</material>
    </gazebo>

    <joint name="${prefix}robotiq_85_right_knuckle_joint" type="continuous">
      <parent link="${prefix}robotiq_85_base_link"/>
      <child link="${prefix}robotiq_85_right_knuckle_link"/>
      <axis xyz="0 0 1"/>
      <origin rpy="0.0 0.0 0.0" xyz="0.05490451627 -0.03060114443 0.0"/>
      <limit lower="-${pi}" upper="${pi}" velocity="100.0" effort="50"/>
      <mimic joint="${prefix}robotiq_85_left_knuckle_joint"/>
      <dynamics damping="100.0" />
    </joint>
    <gazebo reference="${prefix}robotiq_85_right_knuckle_link">
      <kp>1000000.0</kp>
      <kd>100.0</kd>
      <mu1>30.0</mu1>
      <mu2>30.0</mu2>
      <maxVel>1.0</maxVel>
      <minDepth>0.001</minDepth>
      <material>Gazebo/Grey</material>
    </gazebo>


    <link name="${prefix}robotiq_85_left_knuckle_link">
      <visual>
        <geometry>
          <mesh filename="file://$(find robotiq_85_description)/meshes/visual/robotiq_85_knuckle_link.dae"/>
        </geometry>
      </visual>
      <collision>
        <geometry>
          <mesh filename="file://$(find robotiq_85_description)/meshes/collision/robotiq_85_knuckle_link.stl"/>
        </geometry>
      </collision>
      <inertial>
        <mass value="0.018491" />
        <origin xyz="0.0 0.0 0.0" />
        <inertia ixx = "0.000009" ixy = "-0.000001" ixz = "0.000000"
          iyx = "-0.000001" iyy = "0.000001" iyz = "0.000000"
          izx = "0.000000" izy = "0.000000" izz = "0.000010" />
      </inertial>
    </link>

    <link name="${prefix}robotiq_85_right_knuckle_link">
      <visual>
        <geometry>
          <mesh filename="file://$(find robotiq_85_description)/meshes/visual/robotiq_85_knuckle_link.dae"/>
        </geometry>
      </visual>
      <collision>
        <geometry>
          <mesh filename="file://$(find robotiq_85_description)/meshes/collision/robotiq_85_knuckle_link.stl"/>
        </geometry>
      </collision>
      <inertial>
        <mass value="0.018491" />
        <origin xyz="0.0 0.0 0.0" />
        <inertia ixx = "0.000009" ixy = "-0.000001" ixz = "0.000000"
          iyx = "-0.000001" iyy = "0.000001" iyz = "0.000000"
          izx = "0.000000" izy = "0.000000" izz = "0.000010" />
      </inertial>
    </link>

    <joint name="${prefix}robotiq_85_left_finger_joint" type="fixed">
      <parent link="${prefix}robotiq_85_left_knuckle_link"/>
      <child link="${prefix}robotiq_85_left_finger_link"/>
      <origin xyz="-0.00408552455 -0.03148604435 0.0" rpy="0 0 0" />
    </joint>


    <joint name="${prefix}robotiq_85_right_finger_joint" type="fixed">
      <parent link="${prefix}robotiq_85_right_knuckle_link"/>
      <child link="${prefix}robotiq_85_right_finger_link"/>
      <origin xyz="-0.00408552455 -0.03148604435 0.0" rpy="0 0 0" />
    </joint>


    <link name="${prefix}robotiq_85_left_finger_link">
      <visual>
        <geometry>
          <mesh filename="file://$(find robotiq_85_description)/meshes/visual/robotiq_85_finger_link.dae"/>
        </geometry>
      </visual>
      <collision>
        <geometry>
          <mesh filename="file://$(find robotiq_85_description)/meshes/collision/robotiq_85_finger_link.stl"/>
        </geometry>
      </collision>
      <inertial>
        <mass value="0.027309" />
        <origin xyz="0.0 0.0 0.0" />
        <inertia ixx = "0.000003" ixy = "-0.000002" ixz = "0.000000"
          iyx = "-0.000002" iyy = "0.000021" iyz = "0.000000"
          izx = "0.000000" izy = "0.000000" izz = "0.000020" />
      </inertial>
    </link>


    <link name="${prefix}robotiq_85_right_finger_link">
      <visual>
        <geometry>
          <mesh filename="file://$(find robotiq_85_description)/meshes/visual/robotiq_85_finger_link.dae"/>
        </geometry>
      </visual>
      <collision>
        <geometry>
          <mesh filename="file://$(find robotiq_85_description)/meshes/collision/robotiq_85_finger_link.stl"/>
        </geometry>
      </collision>
      <inertial>
        <mass value="0.027309" />
        <origin xyz="0.0 0.0 0.0" />
        <inertia ixx = "0.000003" ixy = "-0.000002" ixz = "0.000000"
          iyx = "-0.000002" iyy = "0.000021" iyz = "0.000000"
          izx = "0.000000" izy = "0.000000" izz = "0.000020" />
      </inertial>
    </link>


    <joint name="${prefix}robotiq_85_left_inner_knuckle_joint" type="continuous">
      <parent link="${prefix}robotiq_85_base_link"/>
      <child link="${prefix}robotiq_85_left_inner_knuckle_link"/>
      <axis xyz="0 0 1"/>
      <origin xyz="0.06142 0.0127 0" rpy="${pi} 0.0 0.0" />
      <limit lower="-${pi}" upper="${pi}" velocity="100.0" effort="0.1"/>
      <mimic joint="${prefix}robotiq_85_left_knuckle_joint" offset="0"/>
    </joint>

    <joint name="${prefix}robotiq_85_right_inner_knuckle_joint" type="continuous">
      <parent link="${prefix}robotiq_85_base_link"/>
      <child link="${prefix}robotiq_85_right_inner_knuckle_link"/>
      <axis xyz="0 0 1"/>
      <origin xyz="0.06142 -0.0127 0" rpy="0 0 0"/>
      <limit lower="-${pi}" upper="${pi}" velocity="100.0" effort="0.1"/>
      <mimic joint="${prefix}robotiq_85_left_knuckle_joint" offset="0"/>
    </joint>

    <link name="${prefix}robotiq_85_left_inner_knuckle_link">
      <visual>
        <geometry>
          <mesh filename="file://$(find robotiq_85_description)/meshes/visual/robotiq_85_inner_knuckle_link.dae"/>
        </geometry>
      </visual>
      <collision>
        <geometry>
          <mesh filename="file://$(find robotiq_85_description)/meshes/collision/robotiq_85_inner_knuckle_link.stl"/>
        </geometry>
      </collision>
      <inertial>
        <mass value="0.029951" />
        <origin xyz="0.0 0.0 0.0" />
        <inertia ixx = "0.000039" ixy = "0.000000" ixz = "0.000000"
          iyx = "0.000000" iyy = "0.000005" iyz = "0.000000"
          izx = "0.000000" izy = "0.000000" izz = "0.000035" />
      </inertial>
    </link>
    <link name="${prefix}robotiq_85_right_inner_knuckle_link">
      <visual>
        <geometry>
          <mesh filename="file://$(find robotiq_85_description)/meshes/visual/robotiq_85_inner_knuckle_link.dae"/>
        </geometry>
      </visual>
      <collision>
        <geometry>
          <mesh filename="file://$(find robotiq_85_description)/meshes/collision/robotiq_85_inner_knuckle_link.stl"/>
        </geometry>
      </collision>
      <inertial>
        <mass value="0.029951" />
        <origin xyz="0.0 0.0 0.0" />
        <inertia ixx = "0.000039" ixy = "0.000000" ixz = "0.000000"
          iyx = "0.000000" iyy = "0.000005" iyz = "0.000000"
          izx = "0.000000" izy = "0.000000" izz = "0.000035" />
      </inertial>
    </link>

    <joint name="${prefix}robotiq_85_left_finger_tip_joint" type="continuous">
      <parent link="${prefix}robotiq_85_left_inner_knuckle_link"/>
      <child link="${prefix}robotiq_85_left_finger_tip_link"/>
      <axis xyz="0 0 1"/>
      <origin xyz="0.04303959807 -0.03759940821 0.0" rpy="0.0 0.0 0.0"/>
      <limit lower="-${pi}" upper="${pi}" velocity="100.0" effort="0.1"/>
      <mimic joint="${prefix}robotiq_85_left_knuckle_joint" multiplier="-1"/>
    </joint>

    <joint name="${prefix}robotiq_85_right_finger_tip_joint" type="continuous">
      <parent link="${prefix}robotiq_85_right_inner_knuckle_link"/>
      <child link="${prefix}robotiq_85_right_finger_tip_link"/>
      <axis xyz="0 0 1"/>
      <origin rpy="0.0 0.0 0.0" xyz="0.04303959807 -0.03759940821  0.0"/>
      <limit lower="-${pi}" upper="${pi}" velocity="100.0" effort="0.1"/>
      <mimic joint="${prefix}robotiq_85_left_knuckle_joint" multiplier="-1"/>
    </joint>

    <link name="${prefix}robotiq_85_left_finger_tip_link">
      <visual>
        <geometry>
          <mesh filename="file://$(find robotiq_85_description)/meshes/visual/robotiq_85_finger_tip_link.dae"/>
        </geometry>
      </visual>
      <collision>
        <geometry>
          <mesh filename="file://$(find robotiq_85_description)/meshes/collision/robotiq_85_finger_tip_link.stl"/>
        </geometry>
      </collision>
      <inertial>
        <mass value="0.019555" />
        <origin xyz="0.0 0.0 0.0" />
        <inertia ixx = "0.000002" ixy = "0.000000" ixz = "0.000000"
          iyx = "0.000000" iyy = "0.000005" iyz = "0.000000"
          izx = "0.000000" izy = "0.000000" izz = "0.000006" />
      </inertial>
    </link>
    <gazebo reference="${prefix}robotiq_85_left_finger_tip_link">
      <kp>1000000.0</kp>
      <kd>100.0</kd>
      <mu1>30.0</mu1>
      <mu2>30.0</mu2>
      <maxVel>1.0</maxVel>
      <minDepth>0.001</minDepth>
      <material>Gazebo/Grey</material>
    </gazebo>

    <link name="${prefix}robotiq_85_right_finger_tip_link">
      <visual>
        <geometry>
          <mesh filename="file://$(find robotiq_85_description)/meshes/visual/robotiq_85_finger_tip_link.dae"/>
        </geometry>
      </visual>
      <collision>
        <geometry>
          <mesh filename="file://$(find robotiq_85_description)/meshes/collision/robotiq_85_finger_tip_link.stl"/>
        </geometry>
      </collision>
      <inertial>
        <mass value="0.019555" />
        <origin xyz="0.0 0.0 0.0" />
        <inertia ixx = "0.000002" ixy = "0.000000" ixz = "0.000000"
          iyx = "0.000000" iyy = "0.000005" iyz = "0.000000"
          izx = "0.000000" izy = "0.000000" izz = "0.000006" />
      </inertial>
    </link>
    <gazebo reference="${prefix}robotiq_85_right_finger_tip_link">
      <kp>1000000.0</kp>
      <kd>100.0</kd>
      <mu1>30.0</mu1>
      <mu2>30.0</mu2>
      <maxVel>1.0</maxVel>
      <minDepth>0.001</minDepth>
      <material>Gazebo/Grey</material>
    </gazebo>-->
    <xacro:robotiq_85_gripper_transmission prefix="${prefix}" />


    <!-- ros2_control part -->
    <!-- NOTE - currently using "system" because it is only supported hardware_interface-type by Gazebo and Ignition -->
    <ros2_control name="${name}" type="system">
      <hardware>
        <xacro:if value="${gazebo_sim}">
          <plugin>gazebo_ros2_control/GazeboSystem</plugin>
        </xacro:if>
        <xacro:if value="${ignition_sim}">
          <plugin>ignition_ros2_control/IgnitionSystem</plugin>
        </xacro:if>
        <xacro:if value="${use_fake_hardware}">
          <plugin>fake_components/GenericSystem</plugin>
          <param name="fake_sensor_commands">${fake_sensor_commands}</param>
          <param name="state_following_offset">0.0</param>
        </xacro:if>
        <xacro:unless value="${use_fake_hardware or gazebo_sim or ignition_sim}">
          <plugin>robotiq_hardware_interface/NOT_IMPLEMENTED_YET</plugin>
          <param name="ADD_GRIPPER_RELEVANT_PARAMETERS">654321</param>
        </xacro:unless>
      </hardware>
      <joint name="${prefix}robotiq_85_left_knuckle_joint">
        <command_interface name="position">
          <param name="min">0.0</param>
          <param name="max">0.085</param>
        </command_interface>
        <command_interface name="velocity">
          <param name="min">0.013</param>
          <param name="max">0.1</param>
        </command_interface>
        <command_interface name="force">
          <param name="min">5.0</param>
          <param name="max">220.0</param>
        </command_interface>
        <state_interface name="position"/>
        <state_interface name="velocity"/>
        <state_interface name="force"/>
      </joint>
      <joint name="${prefix}robotiq_85_right_knuckle_joint">
        <param name="mimic">${prefix}robotiq_85_left_knuckle_joint</param>
        <param name="multiplier">1</param>
        <command_interface name="position">
          <param name="min">0.0</param>
          <param name="max">0.085</param>
        </command_interface>
        <command_interface name="velocity">
          <param name="min">0.013</param>
          <param name="max">0.1</param>
        </command_interface>
        <command_interface name="force">
          <param name="min">5.0</param>
          <param name="max">220.0</param>
        </command_interface>
        <state_interface name="position"/>
        <state_interface name="velocity"/>
        <state_interface name="force"/>
      </joint>
      <joint name="${prefix}robotiq_85_left_inner_knuckle_joint">
        <param name="mimic">${prefix}robotiq_85_left_knuckle_joint</param>
        <param name="multiplier">1</param>
        <command_interface name="position">
          <param name="min">0.0</param>
          <param name="max">0.085</param>
        </command_interface>
        <command_interface name="velocity">
          <param name="min">0.013</param>
          <param name="max">0.1</param>
        </command_interface>
        <command_interface name="force">
          <param name="min">5.0</param>
          <param name="max">220.0</param>
        </command_interface>
        <state_interface name="position"/>
        <state_interface name="velocity"/>
        <state_interface name="force"/>
      </joint>
      <joint name="${prefix}robotiq_85_right_inner_knuckle_joint">
        <param name="mimic">${prefix}robotiq_85_left_knuckle_joint</param>
        <param name="multiplier">1</param>
        <command_interface name="position">
          <param name="min">0.0</param>
          <param name="max">0.085</param>
        </command_interface>
        <command_interface name="velocity">
          <param name="min">0.013</param>
          <param name="max">0.1</param>
        </command_interface>
        <command_interface name="force">
          <param name="min">5.0</param>
          <param name="max">220.0</param>
        </command_interface>
        <state_interface name="position"/>
        <state_interface name="velocity"/>
        <state_interface name="force"/>
      </joint>
      <joint name="${prefix}robotiq_85_left_finger_tip_joint">
        <param name="mimic">${prefix}robotiq_85_left_knuckle_joint</param>
        <param name="multiplier">-1</param>
        <command_interface name="position">
          <param name="min">0.0</param>
          <param name="max">0.085</param>
        </command_interface>
        <command_interface name="velocity">
          <param name="min">0.013</param>
          <param name="max">0.1</param>
        </command_interface>
        <command_interface name="force">
          <param name="min">5.0</param>
          <param name="max">220.0</param>
        </command_interface>
        <state_interface name="position"/>
        <state_interface name="velocity"/>
        <state_interface name="force"/>
      </joint>
      <joint name="${prefix}robotiq_85_right_finger_tip_joint">
        <param name="mimic">${prefix}robotiq_85_left_knuckle_joint</param>
        <param name="multiplier">-1</param>
        <command_interface name="position">
          <param name="min">0.0</param>
          <param name="max">0.085</param>
        </command_interface>
        <command_interface name="velocity">
          <param name="min">0.013</param>
          <param name="max">0.1</param>
        </command_interface>
        <command_interface name="force">
          <param name="min">5.0</param>
          <param name="max">220.0</param>
        </command_interface>
        <state_interface name="position"/>
        <state_interface name="velocity"/>
        <state_interface name="force"/>
      </joint>
    </ros2_control>

  </xacro:macro>
</robot>
